Workbook

Sheet Client Dashboard
A1: BELLA CUCINA — Q1 2026 PAID MEDIA PERFORMANCE REPORT
A4: TOTAL Q1 SPEND | D4: TOTAL CONVERSIONS | G4: LOWEST CPA | J4: BEST PLATFORM
A5: $1,440,829 | D5: 369,900 | G5: $3.08 Google Ads | J5: Google Ads Conv Rate 7.46%
A9: PLATFORM PERFORMANCE | G9: MONTHLY TRENDS
A24: CAMPAIGN EFFICIENCY | G24: FUNNEL SUMMARY
G25: PLATFORM FUNNEL SUMMARY
G26: Platform | H26: Impressions | I26: Clicks | J26: Conv | K26: CTR% | L26: Conv Rate%
G27: Facebook | H27: 46.2M | I27: 1.6M | J27: 70K | K27: 3.51% | L27: 4.32%
G28: Google Ads | H28: 49.4M | I28: 1.7M | J28: 123K | K28: 3.34% | L28: 7.46%
G29: Instagram | H29: 55.9M | I29: 2.2M | J29: 103K | K29: 4.00% | L29: 4.63%
G30: TikTok | H30: 58.1M | I30: 2.1M | J30: 73K | K30: 3.64% | L30: 3.46%
G31: KEY RECOMMENDATIONS — Q2 2026
G32: Increase Google Ads + Instagram budget by 20% — lowest CPA and best conversion rates.
G33: Maintain TikTok spend for awareness only — cheapest reach but weakest conversion rate
G34: Reduce Facebook budget by 15% — highest CPA ($4.85) and lowest conversion rate.
G35: Repeat SpringFeast campaign — most efficient seasonal campaign at $4.03 CPA.
G36: March was strongest month — CPA improved $3.93 → $3.79 as campaigns matured.

Sheet Platform Summary
A1: Platform | B1: Sum of clicks | C1: Sum of impressions | D1: Sum of spend_usd | E1: Sum of conversions | F1: CTR % | G1: CPC | H1: CPA | I1: Conv Rate % | J1: CPM
A2: Facebook | B2: 1619995 | C2: 46175655 | D2: 339218.38 | E2: 69994 | F2: =GETPIVOTDATA("Sum of clicks",$A$1,"platform","Facebook")/GETPIVOTDATA("Sum of impressions",$A$1,"platform","Facebook") -> 0.035083314 | G2: =GETPIVOTDATA("Sum of spend_usd",$A$1,"platform","Facebook")/GETPIVOTDATA("Sum of clicks",$A$1,"platform","Facebook") -> 0.20939471 | H2: =GETPIVOTDATA("Sum of spend_usd",$A$1,"platform","Facebook")/GETPIVOTDATA("Sum of conversions",$A$1,"platform","Facebook") -> 4.8463923 | I2: =GETPIVOTDATA("Sum of conversions",$A$1,"platform","Facebook")/GETPIVOTDATA("Sum of clicks",$A$1,"platform","Facebook") -> 0.043206306 | J2: =(D2/C2)*1000 -> 7.3462603
A3: Google Ads | B3: 1653207 | C3: 49441304 | D3: 379820.97 | E3: 123327 | F3: =GETPIVOTDATA("Sum of clicks",$A$1,"platform","Google Ads")/GETPIVOTDATA("Sum of impressions",$A$1,"platform","Google Ads") -> 0.033437771 | G3: =GETPIVOTDATA("Sum of spend_usd",$A$1,"platform","Google Ads")/GETPIVOTDATA("Sum of clicks",$A$1,"platform","Google Ads") -> 0.22974798 | H3: =GETPIVOTDATA("Sum of spend_usd",$A$1,"platform","Google Ads")/GETPIVOTDATA("Sum of conversions",$A$1,"platform","Google Ads") -> 3.0797876 | I3: =GETPIVOTDATA("Sum of conversions",$A$1,"platform","Google Ads")/GETPIVOTDATA("Sum of clicks",$A$1,"platform","Google Ads") -> 0.074598644 | J3: =D3/C3*1000 -> 7.6822604
A4: Instagram | B4: 2235527 | C4: 55911388 | D4: 384135.33 | E4: 103413 | F4: =GETPIVOTDATA("Sum of clicks",$A$1,"platform","Instagram")/GETPIVOTDATA("Sum of impressions",$A$1,"platform","Instagram") -> 0.039983393 | G4: =GETPIVOTDATA("Sum of spend_usd",$A$1,"platform","Instagram")/GETPIVOTDATA("Sum of clicks",$A$1,"platform","Instagram") -> 0.17183211 | H4: =GETPIVOTDATA("Sum of spend_usd",$A$1,"platform","Instagram")/GETPIVOTDATA("Sum of conversions",$A$1,"platform","Instagram") -> 3.7145749 | I4: =GETPIVOTDATA("Sum of conversions",$A$1,"platform","Instagram")/GETPIVOTDATA("Sum of clicks",$A$1,"platform","Instagram") -> 0.046258891 | J4: =D4/C4*1000 -> 6.8704309
A5: TikTok | B5: 2115520 | C5: 58097005 | D5: 337654.72 | E5: 73166 | F5: =GETPIVOTDATA("Sum of clicks",$A$1,"platform","TikTok")/GETPIVOTDATA("Sum of impressions",$A$1,"platform","TikTok") -> 0.036413581 | G5: =GETPIVOTDATA("Sum of spend_usd",$A$1,"platform","TikTok")/GETPIVOTDATA("Sum of clicks",$A$1,"platform","TikTok") -> 0.15960838 | H5: =GETPIVOTDATA("Sum of spend_usd",$A$1,"platform","TikTok")/GETPIVOTDATA("Sum of conversions",$A$1,"platform","TikTok") -> 4.6149129 | I5: =GETPIVOTDATA("Sum of conversions",$A$1,"platform","TikTok")/GETPIVOTDATA("Sum of clicks",$A$1,"platform","TikTok") -> 0.03458535 | J5: =D5/C5*1000 -> 5.8119127
A6: Grand Total | B6: 7624249 | C6: 209625352 | D6: 1440829.4 | E6: 369900

Sheet Campaign Analysis
A1: Campaign Name | B1: Sum of conversions | C1: Sum of impressions | D1: Sum of clicks | E1: Sum of spend_usd | F1: CTR % | G1: CPC | H1: CPA | I1: Conv Rate % | J1: CPM
A2: BellaCucina_Display_Retargeting | B2: 28121 | C2: 28148982 | D2: 378363 | E2: 86933.18 | F2: =GETPIVOTDATA("Sum of clicks",$A$1,"campaign_name","BellaCucina_Display_Retargeting")/GETPIVOTDATA("Sum of impressions",$A$1,"campaign_name","BellaCucina_Display_Retargeting") -> 0.013441445 | G2: =GETPIVOTDATA("Sum of spend_usd",$A$1,"campaign_name","BellaCucina_Display_Retargeting")/GETPIVOTDATA("Sum of clicks",$A$1,"campaign_name","BellaCucina_Display_Retargeting") -> 0.22976131 | H2: =GETPIVOTDATA("Sum of spend_usd",$A$1,"campaign_name","BellaCucina_Display_Retargeting")/GETPIVOTDATA("Sum of conversions",$A$1,"campaign_name","BellaCucina_Display_Retargeting") -> 3.0913972 | I2: =GETPIVOTDATA("Sum of conversions",$A$1,"campaign_name","BellaCucina_Display_Retargeting")/GETPIVOTDATA("Sum of clicks",$A$1,"campaign_name","BellaCucina_Display_Retargeting") -> 0.074322806 | J2: =GETPIVOTDATA("Sum of spend_usd",$A$1,"campaign_name","BellaCucina_Display_Retargeting")/GETPIVOTDATA("Sum of impressions",$A$1,"campaign_name","BellaCucina_Display_Retargeting")*1000 -> 3.0883241
A3: BellaCucina_EndlessItalianNights | B3: 80172 | C3: 52404449 | D3: 1953040 | E3: 346128.6 | F3: =GETPIVOTDATA("Sum of clicks",$A$1,"campaign_name","BellaCucina_EndlessItalianNights")/GETPIVOTDATA("Sum of impressions",$A$1,"campaign_name","BellaCucina_EndlessItalianNights") -> 0.037268591 | G3: =GETPIVOTDATA("Sum of spend_usd",$A$1,"campaign_name","BellaCucina_EndlessItalianNights")/GETPIVOTDATA("Sum of clicks",$A$1,"campaign_name","BellaCucina_EndlessItalianNights") -> 0.17722556 | H3: =GETPIVOTDATA("Sum of spend_usd",$A$1,"campaign_name","BellaCucina_EndlessItalianNights")/GETPIVOTDATA("Sum of conversions",$A$1,"campaign_name","BellaCucina_EndlessItalianNights") -> 4.3173253 | I3: =GETPIVOTDATA("Sum of conversions",$A$1,"campaign_name","BellaCucina_EndlessItalianNights")/GETPIVOTDATA("Sum of clicks",$A$1,"campaign_name","BellaCucina_EndlessItalianNights") -> 0.04104985 | J3: =GETPIVOTDATA("Sum of spend_usd",$A$1,"campaign_name","BellaCucina_EndlessItalianNights")/GETPIVOTDATA("Sum of impressions",$A$1,"campaign_name","BellaCucina_EndlessItalianNights")*1000 -> 6.6049468
A4: BellaCucina_NewYearNewPasta | B4: 25018 | C4: 16195399 | D4: 608450 | E4: 108932.74 | F4: =GETPIVOTDATA("Sum of clicks",$A$1,"campaign_name","BellaCucina_NewYearNewPasta")/GETPIVOTDATA("Sum of impressions",$A$1,"campaign_name","BellaCucina_NewYearNewPasta") -> 0.037569312 | G4: =GETPIVOTDATA("Sum of spend_usd",$A$1,"campaign_name","BellaCucina_NewYearNewPasta")/GETPIVOTDATA("Sum of clicks",$A$1,"campaign_name","BellaCucina_NewYearNewPasta") -> 0.17903318 | H4: =GETPIVOTDATA("Sum of spend_usd",$A$1,"campaign_name","BellaCucina_NewYearNewPasta")/GETPIVOTDATA("Sum of conversions",$A$1,"campaign_name","BellaCucina_NewYearNewPasta") -> 4.3541746 | I4: =GETPIVOTDATA("Sum of conversions",$A$1,"campaign_name","BellaCucina_NewYearNewPasta")/GETPIVOTDATA("Sum of clicks",$A$1,"campaign_name","BellaCucina_NewYearNewPasta") -> 0.041117594 | J4: =E4/C4*1000 -> 6.7261535
A5: BellaCucina_NewYearNewPasta_Search | B5: 4508 | C5: 1015462 | D5: 58915 | E5: 12960.32 | F5: =GETPIVOTDATA("Sum of clicks",$A$1,"campaign_name","BellaCucina_NewYearNewPasta_Search")/GETPIVOTDATA("Sum of impressions",$A$1,"campaign_name","BellaCucina_NewYearNewPasta_Search") -> 0.058017927 | G5: =GETPIVOTDATA("Sum of spend_usd",$A$1,"campaign_name","BellaCucina_NewYearNewPasta_Search")/GETPIVOTDATA("Sum of clicks",$A$1,"campaign_name","BellaCucina_NewYearNewPasta_Search") -> 0.21998337 | H5: =GETPIVOTDATA("Sum of spend_usd",$A$1,"campaign_name","BellaCucina_NewYearNewPasta_Search")/GETPIVOTDATA("Sum of conversions",$A$1,"campaign_name","BellaCucina_NewYearNewPasta_Search") -> 2.8749601 | I5: =GETPIVOTDATA("Sum of conversions",$A$1,"campaign_name","BellaCucina_NewYearNewPasta_Search")/GETPIVOTDATA("Sum of clicks",$A$1,"campaign_name","BellaCucina_NewYearNewPasta_Search") -> 0.076517016 | J5: =E5/C5*1000 -> 12.762979
A6: BellaCucina_Retargeting | B6: 81656 | C6: 52442017 | D6: 1955971 | E6: 347326.65 | F6: =GETPIVOTDATA("Sum of clicks",$A$1,"campaign_name","BellaCucina_Retargeting")/GETPIVOTDATA("Sum of impressions",$A$1,"campaign_name","BellaCucina_Retargeting") -> 0.037297784 | G6: =GETPIVOTDATA("Sum of spend_usd",$A$1,"campaign_name","BellaCucina_Retargeting")/GETPIVOTDATA("Sum of clicks",$A$1,"campaign_name","BellaCucina_Retargeting") -> 0.17757249 | H6: =GETPIVOTDATA("Sum of spend_usd",$A$1,"campaign_name","BellaCucina_Retargeting")/GETPIVOTDATA("Sum of conversions",$A$1,"campaign_name","BellaCucina_Retargeting") -> 4.253535 | I6: =GETPIVOTDATA("Sum of conversions",$A$1,"campaign_name","BellaCucina_Retargeting")/GETPIVOTDATA("Sum of clicks",$A$1,"campaign_name","BellaCucina_Retargeting") -> 0.04174704 | J6: =E6/C6*1000 -> 6.6230605
A7: BellaCucina_Search_Brand | B7: 27091 | C7: 6131607 | D7: 365185 | E7: 83621.88 | F7: =GETPIVOTDATA("Sum of clicks",$A$1,"campaign_name","BellaCucina_Search_Brand")/GETPIVOTDATA("Sum of impressions",$A$1,"campaign_name","BellaCucina_Search_Brand") -> 0.059557796 | G7: =GETPIVOTDATA("Sum of spend_usd",$A$1,"campaign_name","BellaCucina_Search_Brand")/GETPIVOTDATA("Sum of clicks",$A$1,"campaign_name","BellaCucina_Search_Brand") -> 0.22898498 | H7: =GETPIVOTDATA("Sum of spend_usd",$A$1,"campaign_name","BellaCucina_Search_Brand")/GETPIVOTDATA("Sum of conversions",$A$1,"campaign_name","BellaCucina_Search_Brand") -> 3.0867033 | I7: =GETPIVOTDATA("Sum of conversions",$A$1,"campaign_name","BellaCucina_Search_Brand")/GETPIVOTDATA("Sum of clicks",$A$1,"campaign_name","BellaCucina_Retargeting") -> 0.01385041 | J7: =E7/C7*1000 -> 13.637841
A8: BellaCucina_Search_NonBrand | B8: 26167 | C8: 5851142 | D8: 352530 | E8: 81720.06 | F8: =GETPIVOTDATA("Sum of clicks",$A$1,"campaign_name","BellaCucina_Search_NonBrand")/GETPIVOTDATA("Sum of impressions",$A$1,"campaign_name","BellaCucina_Search_NonBrand") -> 0.060249777 | G8: =GETPIVOTDATA("Sum of spend_usd",$A$1,"campaign_name","BellaCucina_Search_NonBrand")/GETPIVOTDATA("Sum of clicks",$A$1,"campaign_name","BellaCucina_Search_NonBrand") -> 0.23181023 | H8: =GETPIVOTDATA("Sum of spend_usd",$A$1,"campaign_name","BellaCucina_Search_NonBrand")/GETPIVOTDATA("Sum of conversions",$A$1,"campaign_name","BellaCucina_Search_NonBrand") -> 3.1230198 | I8: =GETPIVOTDATA("Sum of conversions",$A$1,"campaign_name","BellaCucina_Search_NonBrand")/GETPIVOTDATA("Sum of clicks",$A$1,"campaign_name","BellaCucina_Search_NonBrand") -> 0.074226307 | J8: =E8/C8*1000 -> 13.966515
A9: BellaCucina_Search_Weekend | B9: 26507 | C9: 5850524 | D9: 354111 | E9: 80605.36 | F9: =GETPIVOTDATA("Sum of clicks",$A$1,"campaign_name","BellaCucina_Search_Weekend")/GETPIVOTDATA("Sum of impressions",$A$1,"campaign_name","BellaCucina_Search_Weekend") -> 0.060526373 | G9: =GETPIVOTDATA("Sum of spend_usd",$A$1,"campaign_name","BellaCucina_Search_Weekend")/GETPIVOTDATA("Sum of clicks",$A$1,"campaign_name","BellaCucina_Search_Weekend") -> 0.22762738 | H9: =GETPIVOTDATA("Sum of spend_usd",$A$1,"campaign_name","BellaCucina_Search_Weekend")/GETPIVOTDATA("Sum of conversions",$A$1,"campaign_name","BellaCucina_Search_Weekend") -> 3.0409084 | I9: =GETPIVOTDATA("Sum of conversions",$A$1,"campaign_name","BellaCucina_Search_Weekend")/GETPIVOTDATA("Sum of clicks",$A$1,"campaign_name","BellaCucina_Search_Weekend") -> 0.07485506 | J9: =E9/C9*1000 -> 13.77746
A10: BellaCucina_SpringFeast | B10: 15585 | C10: 10359364 | D10: 380971 | E10: 67770.16 | F10: =GETPIVOTDATA("Sum of clicks",$A$1,"campaign_name","BellaCucina_SpringFeast")/GETPIVOTDATA("Sum of impressions",$A$1,"campaign_name","BellaCucina_SpringFeast") -> 0.03677552 | G10: =GETPIVOTDATA("Sum of spend_usd",$A$1,"campaign_name","BellaCucina_SpringFeast")/GETPIVOTDATA("Sum of clicks",$A$1,"campaign_name","BellaCucina_SpringFeast") -> 0.17788798 | H10: =GETPIVOTDATA("Sum of spend_usd",$A$1,"campaign_name","BellaCucina_SpringFeast")/GETPIVOTDATA("Sum of conversions",$A$1,"campaign_name","BellaCucina_SpringFeast") -> 4.3484222 | I10: =GETPIVOTDATA("Sum of conversions",$A$1,"campaign_name","BellaCucina_SpringFeast")/GETPIVOTDATA("Sum of clicks",$A$1,"campaign_name","BellaCucina_SpringFeast") -> 0.040908626 | J10: =E10/C10*1000 -> 6.5419228
A11: BellaCucina_SpringFeast_Search | B11: 5254 | C11: 1160856 | D11: 67775 | E11: 16115.84 | F11: =GETPIVOTDATA("Sum of clicks",$A$1,"campaign_name","BellaCucina_SpringFeast_Search")/GETPIVOTDATA("Sum of impressions",$A$1,"campaign_name","BellaCucina_SpringFeast_Search") -> 0.058383641 | G11: =GETPIVOTDATA("Sum of spend_usd",$A$1,"campaign_name","BellaCucina_SpringFeast_Search")/GETPIVOTDATA("Sum of clicks",$A$1,"campaign_name","BellaCucina_SpringFeast_Search") -> 0.23778443 | H11: =GETPIVOTDATA("Sum of spend_usd",$A$1,"campaign_name","BellaCucina_SpringFeast_Search")/GETPIVOTDATA("Sum of conversions",$A$1,"campaign_name","BellaCucina_SpringFeast_Search") -> 3.0673468 | I11: =GETPIVOTDATA("Sum of conversions",$A$1,"campaign_name","BellaCucina_SpringFeast_Search")/GETPIVOTDATA("Sum of clicks",$A$1,"campaign_name","BellaCucina_SpringFeast_Search") -> 0.07752121 | J11: =E11/C11*1000 -> 13.882721
A12: BellaCucina_ValentinesDate | B12: 16556 | C12: 10761589 | D12: 407043 | E12: 72046.99 | F12: =GETPIVOTDATA("Sum of clicks",$A$1,"campaign_name","BellaCucina_ValentinesDate")/GETPIVOTDATA("Sum of impressions",$A$1,"campaign_name","BellaCucina_ValentinesDate") -> 0.037823689 | G12: =GETPIVOTDATA("Sum of spend_usd",$A$1,"campaign_name","BellaCucina_ValentinesDate")/GETPIVOTDATA("Sum of clicks",$A$1,"campaign_name","BellaCucina_ValentinesDate") -> 0.17700093 | H12: =GETPIVOTDATA("Sum of spend_usd",$A$1,"campaign_name","BellaCucina_ValentinesDate")/GETPIVOTDATA("Sum of conversions",$A$1,"campaign_name","BellaCucina_ValentinesDate") -> 4.3517148 | I12: =GETPIVOTDATA("Sum of conversions",$A$1,"campaign_name","BellaCucina_ValentinesDate")/GETPIVOTDATA("Sum of clicks",$A$1,"campaign_name","BellaCucina_ValentinesDate") -> 0.040673835 | J12: =E12/C12*1000 -> 6.6948282
A13: BellaCucina_ValentinesDate_Search | B13: 5679 | C13: 1282731 | D13: 76328 | E13: 17864.33 | F13: =GETPIVOTDATA("Sum of clicks",$A$1,"campaign_name","BellaCucina_ValentinesDate_Search")/GETPIVOTDATA("Sum of impressions",$A$1,"campaign_name","BellaCucina_ValentinesDate_Search") -> 0.059504292 | G13: =GETPIVOTDATA("Sum of spend_usd",$A$1,"campaign_name","BellaCucina_ValentinesDate_Search")/GETPIVOTDATA("Sum of clicks",$A$1,"campaign_name","BellaCucina_ValentinesDate_Search") -> 0.23404688 | H13: =GETPIVOTDATA("Sum of spend_usd",$A$1,"campaign_name","BellaCucina_ValentinesDate_Search")/GETPIVOTDATA("Sum of conversions",$A$1,"campaign_name","BellaCucina_ValentinesDate_Search") -> 3.1456823 | I13: =GETPIVOTDATA("Sum of conversions",$A$1,"campaign_name","BellaCucina_ValentinesDate_Search")/GETPIVOTDATA("Sum of clicks",$A$1,"campaign_name","BellaCucina_ValentinesDate_Search") -> 0.074402578 | J13: =E13/C13*1000 -> 13.926794
A14: BellaCucina_WeekendSpecial | B14: 27586 | C14: 18021230 | D14: 665567 | E14: 118803.29 | F14: =GETPIVOTDATA("Sum of clicks",$A$1,"campaign_name","BellaCucina_WeekendSpecial")/GETPIVOTDATA("Sum of impressions",$A$1,"campaign_name","BellaCucina_WeekendSpecial") -> 0.036932385 | G14: =GETPIVOTDATA("Sum of spend_usd",$A$1,"campaign_name","BellaCucina_WeekendSpecial")/GETPIVOTDATA("Sum of clicks",$A$1,"campaign_name","BellaCucina_WeekendSpecial") -> 0.17849937 | H14: =GETPIVOTDATA("Sum of spend_usd",$A$1,"campaign_name","BellaCucina_WeekendSpecial")/GETPIVOTDATA("Sum of conversions",$A$1,"campaign_name","BellaCucina_WeekendSpecial") -> 4.3066516 | I14: =GETPIVOTDATA("Sum of conversions",$A$1,"campaign_name","BellaCucina_WeekendSpecial")/GETPIVOTDATA("Sum of clicks",$A$1,"campaign_name","BellaCucina_WeekendSpecial") -> 0.041447367 | J14: =E14/C14*1000 -> 6.5924074
A15: Grand Total | B15: 369900 | C15: 209625352 | D15: 7624249 | E15: 1440829.4

Sheet Monthly Trends
A1: Months | B1: Sum of conversions | C1: Sum of impressions | D1: Sum of clicks | E1: Sum of spend_usd | F1: CTR% | G1: CPC | H1: CPA | I1: Conv Rate% | J1: CPM
A2: Jan | B2: 123661 | C2: 70563828 | D2: 2583469 | E2: 484827.67 | F2: =D2/C2 -> 0.036611803 | G2: =E2/D2 -> 0.18766537 | H2: =E2/B2 -> 3.920619 | I2: =B2/D2 -> 0.04786626 | J2: =(E2/C2)*1000 -> 6.8707677
A3: Feb | B3: 116327 | C3: 66404098 | D3: 2402760 | E3: 457164.95 | F3: =D3/C3 -> 0.036183911 | G3: =E3/D3 -> 0.19026659 | H3: =E3/B3 -> 3.9299986 | I3: =B3/D3 -> 0.048413907 | J3: =(E3/C3)*1000 -> 6.8845894
A4: Mar | B4: 129912 | C4: 72657426 | D4: 2638020 | E4: 498836.78 | F4: =D4/C4 -> 0.036307645 | G4: =E4/D4 -> 0.18909515 | H4: =E4/B4 -> 3.8398053 | I4: =B4/D4 -> 0.049246025 | J4: =(E4/C4)*1000 -> 6.8655994
A5: Grand Total | B5: 369900 | C5: 209625352 | D5: 7624249 | E5: 1440829.4

Sheet Funnel Analysis
A1: Stage | B1: Facebook | C1: Google Ads | D1: Instagram | E1: TikTok
A2: Impressions | B2: 46175655 | C2: 49441304 | D2: 55911388 | E2: 58097005
A3: Clicks | B3: 1619995 | C3: 1653207 | D3: 2235527 | E3: 2115520
A4: Conversions | B4: 69994 | C4: 123327 | D4: 103413 | E4: 73166
A5: CTR% | B5: 0.0351 | C5: 0.0334 | D5: 0.04 | E5: 0.0364
A6: Conv Rate% | B6: 0.0432 | C6: 0.0746 | D6: 0.0463 | E6: 0.0346

Sheet Trend and Cohort Analysis
A1: WEEKLY TREND ANALYSIS — Q1 2026
A2: Cohort | B2: Total Conv | C2: Conv Rate% | D2: CTR% | E2: CPA | F2: Spend
A3: January Week 1 | B3: 27774 | C3: 0.0476 | D3: 0.037 | E3: 3.93 | F3: 109153
A4: January Week 2 | B4: 27273 | C4: 0.0482 | D4: 0.0362 | E4: 3.88 | F4: 105845
A5: January Week 3 | B5: 27532 | C5: 0.0482 | D5: 0.0365 | E5: 3.94 | F5: 108516
A6: January Week 4 | B6: 27615 | C6: 0.0476 | D6: 0.0361 | E6: 3.92 | F6: 108301
A7: January Week 5 | B7: 13467 | C7: 0.0477 | D7: 0.0379 | E7: 3.94 | F7: 53013
A8: February Week 1 | B8: 28867 | C8: 0.0493 | D8: 0.0366 | E8: 3.9 | F8: 112439
A9: February Week 2 | B9: 40381 | C9: 0.0475 | D9: 0.0367 | E9: 3.98 | F9: 160654
A10: February Week 3 | B10: 26478 | C10: 0.0487 | D10: 0.0359 | E10: 3.91 | F10: 103551
A11: February Week 4 | B11: 20601 | C11: 0.0488 | D11: 0.0351 | E11: 3.91 | F11: 80520
A12: March Week 1 | B12: 25097 | C12: 0.0496 | D12: 0.0363 | E12: 3.82 | F12: 95964
A13: March Week 2 | B13: 24477 | C13: 0.0492 | D13: 0.0358 | E13: 3.85 | F13: 94116
A14: March Week 3 | B14: 33611 | C14: 0.0491 | D14: 0.0364 | E14: 3.86 | F14: 129667
... A16: March Week 5 | B16: 14961 | C16: 0.0495 | D16: 0.037 | E16: 3.79 | F16: 56742
A18: COHORT COMPARISON — SEASONAL CAMPAIGNS Q1 2026
A19: Cohort | B19: Month | C19: Spend | D19: Conversions | E19: CPA | F19: Conv Rate%
A20: NewYearNewPasta | B20: January | C20: 121893 | D20: 29526 | E20: 4.13 | F20: 0.0442
A21: ValentinesDate | B21: February | C21: 89911 | D21: 22235 | E21: 4.04 | F21: 0.046
A22: SpringFeast | B22: March | C22: 83886 | D22: 20839 | E22: 4.03 | F22: 0.0464

Sheet Platform KPIs
A1: PLATFORM KPI LOOKUP | E1: PLATFORM RANKINGS — Q1 2026
A3: Select Platform from Dropdown Below | E3: Rank | F3: Best CPA | G3: Best CTR% | H3: Most Conversions | I3: Cheapest CPM
A4: Platform: | B4: TikTok | E4: 1st | F4: Google Ads | G4: Instagram | H4: Google Ads | I4: TikTok
A5: Total Spend | B5: =IFERROR(_xlfn.XLOOKUP(B4,'Platform Summary'!$A$2:$A$5,'Platform Summary'!$D$2:$D$5),"") -> 337654.72 | E5: 2nd | F5: Instagram | G5: TikTok | H5: Instagram | I5: Instagram
A6: Total Impressions | B6: =IFERROR(_xlfn.XLOOKUP(B4,'Platform Summary'!$A$2:$A$5,'Platform Summary'!$C$2:$C$5),"") -> 58097005 | E6: 3rd | F6: TikTok | G6: Facebook | H6: TikTok | I6: Facebook
A7: Total Clicks | B7: =IFERROR(_xlfn.XLOOKUP(B4,'Platform Summary'!$A$2:$A$5,'Platform Summary'!$B$2:$B$5),"") -> 2115520 | E7: 4th | F7: Facebook | G7: Google Ads | H7: Facebook | I7: Google Ads
A8: Total Conversions | B8: =IFERROR(_xlfn.XLOOKUP(B4,'Platform Summary'!$A$2:$A$5,'Platform Summary'!$E$2:$E$5),"") -> 73166
A9: CTR % | B9: =IFERROR(_xlfn.XLOOKUP(B4,'Platform Summary'!$A$2:$A$5,'Platform Summary'!$F$2:$F$5),"") -> 0.036413581
A10: CPC | B10: =IFERROR(_xlfn.XLOOKUP(B4,'Platform Summary'!$A$2:$A$5,'Platform Summary'!$G$2:$G$5),"") -> 0.15960838
A11: CPA | B11: =IFERROR(_xlfn.XLOOKUP(B4,'Platform Summary'!$A$2:$A$5,'Platform Summary'!$H$2:$H$5),"") -> 4.6149129
A12: Conv Rate % | B12: =IFERROR(_xlfn.XLOOKUP(B4,'Platform Summary'!$A$2:$A$5,'Platform Summary'!$I$2:$I$5),"") -> 0.03458535
A13: CPM | B13: =IFERROR(_xlfn.XLOOKUP(B4,'Platform Summary'!$A$2:$A$5,'Platform Summary'!$J$2:$J$5),"") -> 5.8119127

Sheet Combined Data
A1: date | B1: campaign_name | C1: ad_group | D1: ad_format | E1: impressions | F1: clicks | G1: spend_usd | H1: video_views | I1: conversions | J1: platform | K1: keyword | L1: match_type | M1: quality_score
A2: 46023 | B2: BellaCucina_EndlessItalianNights | C2: Foodies 18-24 | D2: Video | E2: 123810 | F2: 3701 | G2: 627.92 | H2: 92175 | I2: 94 | J2: TikTok
A3: 46023 | B3: BellaCucina_EndlessItalianNights | C3: Families 25-34 | D3: Video | E3: 53434 | F3: 2110 | G3: 370.7 | H3: 38937 | I3: 69 | J3: TikTok
A4: 46023 | B4: BellaCucina_Retargeting | C4: Website Visitors | D4: Video | E4: 43905 | F4: 1299 | G4: 193.95 | H4: 34254 | I4: 47 | J4: TikTok
A5: 46023 | B5: BellaCucina_Retargeting | C5: App Users | D5: Video | E5: 125181 | F5: 4997 | G5: 783.43 | H5: 95753 | I5: 146 | J5: TikTok
A6: 46023 | B6: BellaCucina_NewYearNewPasta | C6: Foodies 18-24 | D6: Video | E6: 40851 | F6: 1670 | G6: 244.47 | H6: 31139 | I6: 48 | J6: TikTok
A7: 46023 | B7: BellaCucina_NewYearNewPasta | C7: Families 25-34 | D7: Video | E7: 68221 | F7: 3020 | G7: 463.46 | H7: 49751 | I7: 74 | J7: TikTok
A8: 46024 | B8: BellaCucina_EndlessItalianNights | C8: Foodies 18-24 | D8: Video | E8: 85082 | F8: 3255 | G8: 560.79 | H8: 67467 | I8: 116 | J8: TikTok
A9: 46024 | B9: BellaCucina_EndlessItalianNights | C9: Families 25-34 | D9: Video | E9: 89615 | F9: 2629 | G9: 398.89 | H9: 70156 | I9: 118 | J9: TikTok
A10: 46024 | B10: BellaCucina_Retargeting | C10: Website Visitors | D10: Video | E10: 87400 | F10: 3305 | G10: 555.84 | H10: 63328 | I10: 92 | J10: TikTok
A11: 46024 | B11: BellaCucina_Retargeting | C11: App Users | D11: Video | E11: 77930 | F11: 3487 | G11: 607.48 | H11: 62862 | I11: 111 | J11: TikTok
A12: 46024 | B12: BellaCucina_NewYearNewPasta | C12: Foodies 18-24 | D12: Video | E12: 99429 | F12: 3858 | G12: 596.42 | H12: 75269 | I12: 105 | J12: TikTok
A13: 46024 | B13: BellaCucina_NewYearNewPasta | C13: Families 25-34 | D13: Video | E13: 74993 | F13: 2994 | G13: 501.02 | H13: 54530 | I13: 115 | J13: TikTok
... A1081: 46112 | B1081: BellaCucina_SpringFeast | C1081: Families 25-44 | D1081: Stories | E1081: 69405 | F1081: 2380 | G1081: 450.64 | H1081: 56339 | I1081: 133 | J1081: Instagram
A1082: 46023 | B1082: BellaCucina_Search_Brand | C1082: Core Brand | E1082: 20418 | F1082: 1408 | G1082: 376.86 | H1082: 376.86 | I1082: 82 | J1082: Google Ads | K1082: bella cucina restaurant | L1082: Exact | M1082: 9
A1083: 46023 | B1083: BellaCucina_Search_Brand | C1083: Core Brand | E1083: 33621 | F1083: 1815 | G1083: 394.19 | H1083: 394.19 | I1083: 165 | J1083: Google Ads | K1083: bella cucina near me | L1083: Phrase | M1083: 8
A1084: 46023 | B1084: BellaCucina_Search_NonBrand | C1084: Category | E1084: 20847 | F1084: 1026 | G1084: 248.87 | I1084: 86 | J1084: Google Ads | K1084: italian food near me | L1084: Phrase | M1084: 7
A1085: 46023 | B1085: BellaCucina_Search_NonBrand | C1085: Competitor | E1085: 25344 | F1085: 1477 | G1085: 279.33 | I1085: 86 | J1085: Google Ads | K1085: competitor italian chain | L1085: Broad | M1085: 4
A1086: 46023 | B1086: BellaCucina_Display_Retargeting | C1086: Cart Abandoners | E1086: 117973 | F1086: 1578 | G1086: 304.98 | I1086: 101 | J1086: Google Ads | K1086: N/A | L1086: N/A | M1086: N/A
A1087: 46023 | B1087: BellaCucina_Display_Retargeting | C1087: Homepage Visitors | E1087: 148335 | F1087: 1638 | G1087: 408.78 | I1087: 143 | J1087: Google Ads | K1087: N/A | L1087: N/A | M1087: N/A
A1088: 46023 | B1088: BellaCucina_Search_Weekend | C1088: Weekend Dining | E1088: 37676 | F1088: 2436 | G1088: 554.85 | I1088: 156 | J1088: Google Ads | K1088: weekend italian dinner | L1088: Phrase | M1088: 8
A1089: 46023 | B1089: BellaCucina_Search_Weekend | C1089: Weekend Dining | E1089: 15854 | F1089: 1039 | G1089: 197.66 | I1089: 70 | J1089: Google Ads | K1089: endless pasta deal | L1089: Exact | M1089: 8
A1090: 46023 | B1090: BellaCucina_NewYearNewPasta_Search | C1090: New Year Dining | E1090: 29611 | F1090: 1518 | G1090: 390.65 | I1090: 129 | J1090: Google Ads | K1090: new year dinner restaurant | L1090: Phrase | M1090: 7
A1091: 46024 | B1091: BellaCucina_Search_Brand | C1091: Core Brand | E1091: 18725 | F1091: 1187 | G1091: 294.04 | I1091: 68 | J1091: Google Ads | K1091: bella cucina restaurant | L1091: Exact | M1091: 9
A1092: 46024 | B1092: BellaCucina_Search_Brand | C1092: Core Brand | E1092: 10555 | F1092: 661 | G1092: 129.83 | I1092: 45 | J1092: Google Ads | K1092: bella cucina near me | L1092: Phrase | M1092: 8
A1093: 46024 | B1093: BellaCucina_Search_NonBrand | C1093: Category | E1093: 23962 | F1093: 1511 | G1093: 294.85 | I1093: 107 | J1093: Google Ads | K1093: italian food near me | L1093: Phrase | M1093: 7
A1094: 46024 | B1094: BellaCucina_Search_NonBrand | C1094: Competitor | E1094: 38992 | F1094: 2676 | G1094: 504.88 | I1094: 157 | J1094: Google Ads | K1094: competitor italian chain | L1094: Broad | M1094: 4
A1095: 46024 | B1095: BellaCucina_Display_Retargeting | C1095: Cart Abandoners | E1095: 106142 | F1095: 1480 | G1095: 323.24 | I1095: 138 | J1095: Google Ads | K1095: N/A | L1095: N/A | M1095: N/A
... A1898: 46112 | B1898: BellaCucina_SpringFeast_Search | C1898: Spring Dining | E1898: 44145 | F1898: 2507 | G1898: 613.76 | I1898: 208 | J1898: Google Ads | K1898: best spring pasta deal | L1898: Exact | M1898: 8
A1899: 46023 | B1899: BellaCucina_EndlessItalianNights | C1899: Families 25-44 | D1899: Single Image | E1899: 56832 | F1899: 1701 | G1899: 340.36 | H1899: 43985 | I1899: 80 | J1899: Facebook
A1900: 46023 | B1900: BellaCucina_EndlessItalianNights | C1900: Lookalike 1% Diners | D1900: Carousel | E1900: 59548 | F1900: 1934 | G1900: 452.32 | H1900: 45873 | I1900: 78 | J1900: Facebook
A1901: 46023 | B1901: BellaCucina_Retargeting | C1901: Website Visitors | D1901: Dynamic | E1901: 38305 | F1901: 1272 | G1901: 263.49 | H1901: 29500 | I1901: 67 | J1901: Facebook
A1902: 46023 | B1902: BellaCucina_Retargeting | C1902: Menu Viewers | D1902: Carousel | E1902: 99717 | F1902: 3739 | G1902: 792.56 | H1902: 74710 | I1902: 174 | J1902: Facebook
A1903: 46023 | B1903: BellaCucina_NewYearNewPasta | C1903: Families 25-44 | D1903: Video | E1903: 54687 | F1903: 2214 | G1903: 459.34 | H1903: 39813 | I1903: 121 | J1903: Facebook
A1904: 46023 | B1904: BellaCucina_NewYearNewPasta | C1904: Lookalike 1% Diners | D1904: Carousel | E1904: 40085 | F1904: 1183 | G1904: 232.53 | H1904: 31655 | I1904: 50 | J1904: Facebook
A1905: 46024 | B1905: BellaCucina_EndlessItalianNights | C1905: Families 25-44 | D1905: Carousel | E1905: 98247 | F1905: 4060 | G1905: 736.33 | H1905: 74830 | I1905: 196 | J1905: Facebook
A1906: 46024 | B1906: BellaCucina_EndlessItalianNights | C1906: Lookalike 1% Diners | D1906: Carousel | E1906: 92115 | F1906: 3026 | G1906: 625.27 | H1906: 72261 | I1906: 111 | J1906: Facebook
A1907: 46024 | B1907: BellaCucina_Retargeting | C1907: Website Visitors | D1907: Dynamic | E1907: 32888 | F1907: 1322 | G1907: 256.39 | H1907: 26795 | I1907: 62 | J1907: Facebook
A1908: 46024 | B1908: BellaCucina_Retargeting | C1908: Menu Viewers | D1908: Carousel | E1908: 105851 | F1908: 3471 | G1908: 759.33 | H1908: 79666 | I1908: 158 | J1908: Facebook
A1909: 46024 | B1909: BellaCucina_NewYearNewPasta | C1909: Families 25-44 | D1909: Video | E1909: 90031 | F1909: 2904 | G1909: 545.71 | H1909: 71928 | I1909: 96 | J1909: Facebook
...

Sheet Tiktok Raw
A1: date | B1: campaign_name | C1: ad_group | D1: ad_format | E1: impressions | F1: clicks | G1: spend_usd | H1: video_views | I1: conversions | J1: platform
A2: 46023 | B2: BellaCucina_EndlessItalianNights | C2: Foodies 18-24 | D2: Video | E2: 123810 | F2: 3701 | G2: 627.92 | H2: 92175 | I2: 94 | J2: TikTok
A3: 46023 | B3: BellaCucina_EndlessItalianNights | C3: Families 25-34 | D3: Video | E3: 53434 | F3: 2110 | G3: 370.7 | H3: 38937 | I3: 69 | J3: TikTok
A4: 46023 | B4: BellaCucina_Retargeting | C4: Website Visitors | D4: Video | E4: 43905 | F4: 1299 | G4: 193.95 | H4: 34254 | I4: 47 | J4: TikTok
A5: 46023 | B5: BellaCucina_Retargeting | C5: App Users | D5: Video | E5: 125181 | F5: 4997 | G5: 783.43 | H5: 95753 | I5: 146 | J5: TikTok
A6: 46023 | B6: BellaCucina_NewYearNewPasta | C6: Foodies 18-24 | D6: Video | E6: 40851 | F6: 1670 | G6: 244.47 | H6: 31139 | I6: 48 | J6: TikTok
A7: 46023 | B7: BellaCucina_NewYearNewPasta | C7: Families 25-34 | D7: Video | E7: 68221 | F7: 3020 | G7: 463.46 | H7: 49751 | I7: 74 | J7: TikTok
A8: 46024 | B8: BellaCucina_EndlessItalianNights | C8: Foodies 18-24 | D8: Video | E8: 85082 | F8: 3255 | G8: 560.79 | H8: 67467 | I8: 116 | J8: TikTok
A9: 46024 | B9: BellaCucina_EndlessItalianNights | C9: Families 25-34 | D9: Video | E9: 89615 | F9: 2629 | G9: 398.89 | H9: 70156 | I9: 118 | J9: TikTok
A10: 46024 | B10: BellaCucina_Retargeting | C10: Website Visitors | D10: Video | E10: 87400 | F10: 3305 | G10: 555.84 | H10: 63328 | I10: 92 | J10: TikTok
A11: 46024 | B11: BellaCucina_Retargeting | C11: App Users | D11: Video | E11: 77930 | F11: 3487 | G11: 607.48 | H11: 62862 | I11: 111 | J11: TikTok
A12: 46024 | B12: BellaCucina_NewYearNewPasta | C12: Foodies 18-24 | D12: Video | E12: 99429 | F12: 3858 | G12: 596.42 | H12: 75269 | I12: 105 | J12: TikTok
A13: 46024 | B13: BellaCucina_NewYearNewPasta | C13: Families 25-34 | D13: Video | E13: 74993 | F13: 2994 | G13: 501.02 | H13: 54530 | I13: 115 | J13: TikTok
... A541: 46112 | B541: BellaCucina_SpringFeast | C541: Families 25-34 | D541: Video | E541: 124893 | F541: 3926 | G541: 657.78 | H541: 91570 | I541: 152 | J541: TikTok

Sheet Instagram Raw
A1: date | B1: campaign_name | C1: ad_group | D1: ad_format | E1: impressions | F1: clicks | G1: spend_usd | H1: reach | I1: conversions | J1: platform
A2: 46023 | B2: BellaCucina_EndlessItalianNights | C2: Foodies 18-34 | D2: Reels | E2: 84474 | F2: 3693 | G2: 671.27 | H2: 65126 | I2: 124 | J2: Instagram
A3: 46023 | B3: BellaCucina_EndlessItalianNights | C3: Families 25-44 | D3: Reels | E3: 121867 | F3: 5033 | G3: 848.61 | H3: 96429 | I3: 184 | J3: Instagram
A4: 46023 | B4: BellaCucina_Retargeting | C4: Profile Visitors | D4: Reels | E4: 82873 | F4: 2839 | G4: 439.2 | H4: 59792 | I4: 161 | J4: Instagram
A5: 46023 | B5: BellaCucina_Retargeting | C5: Post Engagers | D5: Stories | E5: 54623 | F5: 2416 | G5: 406.34 | H5: 40246 | I5: 115 | J5: Instagram
A6: 46023 | B6: BellaCucina_NewYearNewPasta | C6: Foodies 18-34 | D6: Reels | E6: 96628 | F6: 3728 | G6: 597.38 | H6: 78632 | I6: 197 | J6: Instagram
A7: 46023 | B7: BellaCucina_NewYearNewPasta | C7: Families 25-44 | D7: Stories | E7: 49583 | F7: 1710 | G7: 329.81 | H7: 35890 | I7: 93 | J7: Instagram
A8: 46024 | B8: BellaCucina_EndlessItalianNights | C8: Foodies 18-34 | D8: Reels | E8: 36424 | F8: 1396 | G8: 230.92 | H8: 30369 | I8: 63 | J8: Instagram
A9: 46024 | B9: BellaCucina_EndlessItalianNights | C9: Families 25-44 | D9: Feed | E9: 109981 | F9: 4402 | G9: 803.63 | H9: 84777 | I9: 161 | J9: Instagram
A10: 46024 | B10: BellaCucina_Retargeting | C10: Profile Visitors | D10: Reels | E10: 103354 | F10: 3931 | G10: 774.66 | H10: 83631 | I10: 173 | J10: Instagram
A11: 46024 | B11: BellaCucina_Retargeting | C11: Post Engagers | D11: Feed | E11: 63692 | F11: 2437 | G11: 461.45 | H11: 53317 | I11: 122 | J11: Instagram
A12: 46024 | B12: BellaCucina_NewYearNewPasta | C12: Foodies 18-34 | D12: Reels | E12: 125757 | F12: 4966 | G12: 788.56 | H12: 100231 | I12: 282 | J12: Instagram
A13: 46024 | B13: BellaCucina_NewYearNewPasta | C13: Families 25-44 | D13: Stories | E13: 42165 | F13: 1891 | G13: 338.11 | H13: 31344 | I13: 66 | J13: Instagram
... A541: 46112 | B541: BellaCucina_SpringFeast | C541: Families 25-44 | D541: Stories | E541: 69405 | F541: 2380 | G541: 450.64 | H541: 56339 | I541: 133 | J541: Instagram

Sheet Google Raw
A1: date | B1: campaign_name | C1: ad_group | D1: keyword | E1: match_type | F1: impressions | G1: clicks | H1: spend_usd | I1: conversions | J1: quality_score | K1: platform
A2: 46023 | B2: BellaCucina_Search_Brand | C2: Core Brand | D2: bella cucina restaurant | E2: Exact | F2: 20418 | G2: 1408 | H2: 376.86 | I2: 82 | J2: 9 | K2: Google Ads
A3: 46023 | B3: BellaCucina_Search_Brand | C3: Core Brand | D3: bella cucina near me | E3: Phrase | F3: 33621 | G3: 1815 | H3: 394.19 | I3: 165 | J3: 8 | K3: Google Ads
A4: 46023 | B4: BellaCucina_Search_NonBrand | C4: Category | D4: italian food near me | E4: Phrase | F4: 20847 | G4: 1026 | H4: 248.87 | I4: 86 | J4: 7 | K4: Google Ads
A5: 46023 | B5: BellaCucina_Search_NonBrand | C5: Competitor | D5: competitor italian chain | E5: Broad | F5: 25344 | G5: 1477 | H5: 279.33 | I5: 86 | J5: 4 | K5: Google Ads
A6: 46023 | B6: BellaCucina_Display_Retargeting | C6: Cart Abandoners | D6: N/A | E6: N/A | F6: 117973 | G6: 1578 | H6: 304.98 | I6: 101 | J6: N/A | K6: Google Ads
A7: 46023 | B7: BellaCucina_Display_Retargeting | C7: Homepage Visitors | D7: N/A | E7: N/A | F7: 148335 | G7: 1638 | H7: 408.78 | I7: 143 | J7: N/A | K7: Google Ads
A8: 46023 | B8: BellaCucina_Search_Weekend | C8: Weekend Dining | D8: weekend italian dinner | E8: Phrase | F8: 37676 | G8: 2436 | H8: 554.85 | I8: 156 | J8: 8 | K8: Google Ads
A9: 46023 | B9: BellaCucina_Search_Weekend | C9: Weekend Dining | D9: endless pasta deal | E9: Exact | F9: 15854 | G9: 1039 | H9: 197.66 | I9: 70 | J9: 8 | K9: Google Ads
A10: 46023 | B10: BellaCucina_NewYearNewPasta_Search | C10: New Year Dining | D10: new year dinner restaurant | E10: Phrase | F10: 29611 | G10: 1518 | H10: 390.65 | I10: 129 | J10: 7 | K10: Google Ads
A11: 46024 | B11: BellaCucina_Search_Brand | C11: Core Brand | D11: bella cucina restaurant | E11: Exact | F11: 18725 | G11: 1187 | H11: 294.04 | I11: 68 | J11: 9 | K11: Google Ads
A12: 46024 | B12: BellaCucina_Search_Brand | C12: Core Brand | D12: bella cucina near me | E12: Phrase | F12: 10555 | G12: 661 | H12: 129.83 | I12: 45 | J12: 8 | K12: Google Ads
A13: 46024 | B13: BellaCucina_Search_NonBrand | C13: Category | D13: italian food near me | E13: Phrase | F13: 23962 | G13: 1511 | H13: 294.85 | I13: 107 | J13: 7 | K13: Google Ads
... A818: 46112 | B818: BellaCucina_SpringFeast_Search | C818: Spring Dining | D818: best spring pasta deal | E818: Exact | F818: 44145 | G818: 2507 | H818: 613.76 | I818: 208 | J818: 8 | K818: Google Ads

Sheet Facebook Raw
A1: date | B1: campaign_name | C1: ad_group | D1: ad_format | E1: impressions | F1: clicks | G1: spend_usd | H1: reach | I1: conversions | J1: platform
A2: 46023 | B2: BellaCucina_EndlessItalianNights | C2: Families 25-44 | D2: Single Image | E2: 56832 | F2: 1701 | G2: 340.36 | H2: 43985 | I2: 80 | J2: Facebook
A3: 46023 | B3: BellaCucina_EndlessItalianNights | C3: Lookalike 1% Diners | D3: Carousel | E3: 59548 | F3: 1934 | G3: 452.32 | H3: 45873 | I3: 78 | J3: Facebook
A4: 46023 | B4: BellaCucina_Retargeting | C4: Website Visitors | D4: Dynamic | E4: 38305 | F4: 1272 | G4: 263.49 | H4: 29500 | I4: 67 | J4: Facebook
A5: 46023 | B5: BellaCucina_Retargeting | C5: Menu Viewers | D5: Carousel | E5: 99717 | F5: 3739 | G5: 792.56 | H5: 74710 | I5: 174 | J5: Facebook
A6: 46023 | B6: BellaCucina_NewYearNewPasta | C6: Families 25-44 | D6: Video | E6: 54687 | F6: 2214 | G6: 459.34 | H6: 39813 | I6: 121 | J6: Facebook
A7: 46023 | B7: BellaCucina_NewYearNewPasta | C7: Lookalike 1% Diners | D7: Carousel | E7: 40085 | F7: 1183 | G7: 232.53 | H7: 31655 | I7: 50 | J7: Facebook
A8: 46024 | B8: BellaCucina_EndlessItalianNights | C8: Families 25-44 | D8: Carousel | E8: 98247 | F8: 4060 | G8: 736.33 | H8: 74830 | I8: 196 | J8: Facebook
A9: 46024 | B9: BellaCucina_EndlessItalianNights | C9: Lookalike 1% Diners | D9: Carousel | E9: 92115 | F9: 3026 | G9: 625.27 | H9: 72261 | I9: 111 | J9: Facebook
A10: 46024 | B10: BellaCucina_Retargeting | C10: Website Visitors | D10: Dynamic | E10: 32888 | F10: 1322 | G10: 256.39 | H10: 26795 | I10: 62 | J10: Facebook
A11: 46024 | B11: BellaCucina_Retargeting | C11: Menu Viewers | D11: Carousel | E11: 105851 | F11: 3471 | G11: 759.33 | H11: 79666 | I11: 158 | J11: Facebook
A12: 46024 | B12: BellaCucina_NewYearNewPasta | C12: Families 25-44 | D12: Video | E12: 90031 | F12: 2904 | G12: 545.71 | H12: 71928 | I12: 96 | J12: Facebook
A13: 46024 | B13: BellaCucina_NewYearNewPasta | C13: Lookalike 1% Diners | D13: Carousel | E13: 59724 | F13: 2077 | G13: 494.83 | H13: 47598 | I13: 61 | J13: Facebook
... A541: 46112 | B541: BellaCucina_SpringFeast | C541: Foodies 25-44 | D541: Single Image | E541: 80319 | F541: 2485 | G541: 480.79 | H541: 63829 | I541: 78 | J541: Facebook

Sheet chart data
A2: Platform | B2: Sum of spend_usd
A3: Facebook | B3: 339218.38 | D3: Platform | E3: CTR % | F3: Conv Rate
A4: Google Ads | B4: 379820.97 | D4: Facebook | E4: 0.035083314 | F4: 0.043206306
A5: Instagram | B5: 384135.33 | D5: Google Ads | E5: 0.033437771 | F5: 0.074598644
A6: TikTok | B6: 337654.72 | D6: Instagram | E6: 0.039983393 | F6: 0.046258891
D7: TikTok | E7: 0.036413581 | F7: 0.03458535
D11: Platform | E11: CPC | F11: CPA | G11: CPM
D12: Facebook | E12: 0.20939471 | F12: 4.8463923 | G12: 7.3462603
D13: Google Ads | E13: 0.22974798 | F13: 3.0797876 | G13: 7.6822604
D14: Instagram | E14: 0.17183211 | F14: 3.7145749 | G14: 6.8704309
D15: TikTok | E15: 0.15960838 | F15: 4.6149129 | G15: 5.8119127
B20: Campaign Name | C20: Sum of spend_usd
B21: BellaCucina_Display_Retargeting | C21: 86933.18 | J21: Campaign Name | K21: Conv Rate % | L21: CTR %
B22: BellaCucina_EndlessItalianNights | C22: 346128.6 | J22: BellaCucina_Display_Retargeting | K22: 0.074322806 | L22: 0.013441445
B23: BellaCucina_NewYearNewPasta | C23: 108932.74 | J23: BellaCucina_EndlessItalianNights | K23: 0.04104985 | L23: 0.037268591
B24: BellaCucina_NewYearNewPasta_Search | C24: 12960.32 | J24: BellaCucina_NewYearNewPasta | K24: 0.041117594 | L24: 0.037569312
B25: BellaCucina_Retargeting | C25: 347326.65 | J25: BellaCucina_NewYearNewPasta_Search | K25: 0.076517016 | L25: 0.058017927
B26: BellaCucina_Search_Brand | C26: 83621.88 | J26: BellaCucina_Retargeting | K26: 0.04174704 | L26: 0.037297784
B27: BellaCucina_Search_NonBrand | C27: 81720.06 | J27: BellaCucina_Search_Brand | K27: 0.01385041 | L27: 0.059557796
B28: BellaCucina_Search_Weekend | C28: 80605.36 | J28: BellaCucina_Search_NonBrand | K28: 0.074226307 | L28: 0.060249777
B29: BellaCucina_SpringFeast | C29: 67770.16 | J29: BellaCucina_Search_Weekend | K29: 0.07485506 | L29: 0.060526373
B30: BellaCucina_SpringFeast_Search | C30: 16115.84 | J30: BellaCucina_SpringFeast | K30: 0.040908626 | L30: 0.03677552
B31: BellaCucina_ValentinesDate | C31: 72046.99 | J31: BellaCucina_SpringFeast_Search | K31: 0.07752121 | L31: 0.058383641
B32: BellaCucina_ValentinesDate_Search | C32: 17864.33 | J32: BellaCucina_ValentinesDate | K32: 0.040673835 | L32: 0.037823689
B33: BellaCucina_WeekendSpecial | C33: 118803.29 | J33: BellaCucina_ValentinesDate_Search | K33: 0.074402578 | L33: 0.059504292
J34: BellaCucina_WeekendSpecial | K34: 0.041447367 | L34: 0.036932385
E40: Campaign Name | F40: CPA | G40: CPM
E41: BellaCucina_Display_Retargeting | F41: 3.0913972 | G41: 3.0883241 | L41: Campaign Name | M41: CPC
E42: BellaCucina_EndlessItalianNights | F42: 4.3173253 | G42: 6.6049468 | L42: BellaCucina_Display_Retargeting | M42: 0.22976131
E43: BellaCucina_NewYearNewPasta | F43: 4.3541746 | G43: 6.7261535 | L43: BellaCucina_EndlessItalianNights | M43: 0.17722556
E44: BellaCucina_NewYearNewPasta_Search | F44: 2.8749601 | G44: 12.762979 | L44: BellaCucina_NewYearNewPasta | M44: 0.17903318
E45: BellaCucina_Retargeting | F45: 4.253535 | G45: 6.6230605 | L45: BellaCucina_NewYearNewPasta_Search | M45: 0.21998337
E46: BellaCucina_Search_Brand | F46: 3.0867033 | G46: 13.637841 | L46: BellaCucina_Retargeting | M46: 0.17757249
E47: BellaCucina_Search_NonBrand | F47: 3.1230198 | G47: 13.966515 | L47: BellaCucina_Search_Brand | M47: 0.22898498
E48: BellaCucina_Search_Weekend | F48: 3.0409084 | G48: 13.77746 | L48: BellaCucina_Search_NonBrand | M48: 0.23181023
E49: BellaCucina_SpringFeast | F49: 4.3484222 | G49: 6.5419228 | L49: BellaCucina_Search_Weekend | M49: 0.22762738
E50: BellaCucina_SpringFeast_Search | F50: 3.0673468 | G50: 13.882721 | L50: BellaCucina_SpringFeast | M50: 0.17788798
E51: BellaCucina_ValentinesDate | F51: 4.3517148 | G51: 6.6948282 | L51: BellaCucina_SpringFeast_Search | M51: 0.23778443
E52: BellaCucina_ValentinesDate_Search | F52: 3.1456823 | G52: 13.926794 | L52: BellaCucina_ValentinesDate | M52: 0.17700093
E53: BellaCucina_WeekendSpecial | F53: 4.3066516 | G53: 6.5924074 | L53: BellaCucina_ValentinesDate_Search | M53: 0.23404688
...
